Workbook

Sheet PEM Metrics (UAT)
B2: Equipment Category - "E"
B3: UAT for the Month of Aug-26
B4: Plants | C4: Equipment Availability (%) | D4: Unplanned downtime (Hrs) | E4: MTBF | F4: MTTR | G4: PM Compliance % | H4: A Class Machines only for E Category | I4: BD Occurences | J4: Plant SPOC Confirmation | K4: Remarks | N4: Formulae :
B5: TASL- NGP | C5: =((744*41)-D5)/(744*41) -> 0.92820614 | D5: 2190 | E5: =((744*41)-D5)/260 -> 108.9 | F5: =D5/260 -> 8.4230769 | G5: =55/64 -> 0.859375 | H5: 41 | I5: 260 | N5: Equipment Availability % = | O5: Sum of Available Hours- Breakdown Hours) / Sum of Available Hours
B6: TASL-BLR | C6: =((744*48)-D6)/(744*48) -> 0.99770049 | D6: 82.12 | E6: =((744*48)-D6)/21 -> 1696.661 | F6: =D6/21 -> 3.9104762 | G6: 0 | H6: 48 | I6: 21 | J6: Yes | N6: MTBF = | O6: Sum of Operating hours - Breakdown hours / Occurences
B7: TCOE | C7: =((744*120)-D7)/(744*120) -> 0.99993795 | D7: 5.54 | E7: =((744*120)-D7)/1 -> 89274.46 | F7: =D7/1 -> 5.54 | G7: =34/34 -> 1 | H7: 120 | I7: 1 | J7: Yes | K7: The reported unplanned downtime of 5.54 hours is incorrect in actual . The TCOE production team generates/reports breakdown notifications through MES, which is currently the official data source for PEM metrics. Following the implementation of the QR code feature in SAP S/4HANA, the team has aligned and starting the use of SAP Fiori app. We aim to complete the migration to SAP by the end of October 2026; until then, all PEM metrics should continue to be sourced from MES. | N7: MTTR = | O7: Breakdown Hours / No of Breakdown Occurrences
B8: TSAL | C8: =((744*77)-D8)/(744*77) -> 0.99441052 | D8: 320.21 | E8: =((744*77)-D8)/89 -> 640.08753 | F8: =D8/89 -> 3.5978652 | G8: =114/114 -> 1 | H8: 77 | I8: 89 | N8: PM Compliance % = | O8: Closed PM Orders / Total PM Orders
B9: TASL-H01 | C9: =(418.5-D9)/418.5 -> 0.99990442 | D9: 0.04 | E9: =((418.5*19)-D9)/1 -> 7951.46 | F9: =D9/1 -> 0.04 | G9: =19/19 -> 1 | H9: 19 | I9: 1 | N9: Operating Hours = | O9: Available Hours- Breakdown Hours
B10: TBAL | C10: =(418.5-D10)/418.5 -> 1 | D10: 0 | E10: =(((418.5*14)-D10)/1) -> 5859 | F10: =D10/1 -> 0 | G10: =13/18 -> 0.72222222 | H10: 14 | I10: 0
B11: TLMAL | C11: =(418.5-D11)/418.5 -> 1 | D11: 0 | E11: =(((418.5*21)-D11)/1) -> 8788.5 | F11: =D11/1 -> 0 | G11: =19/19 -> 1 | H11: 21 | I11: 0
B12: MCA | C12: 1 | D12: 0 | E12: =(((418.5*1)-D12)/1) -> 418.5 | F12: =D12/1 -> 0 | G12: =1/1 -> 1 | H12: 1 | I12: 0 | J12: Yes

Sheet Breakdown Report IW28
A1: Typ | B1: Equipment | C1: Equipment Category | D1: Order | E1: Notification | F1: Description of technical object | G1: Description | H1: Malf.Start | I1: MalfEnd | J1: MalfStrt | K1: Malf.end | L1: Downtime | M1: Date | N1: Time | O1: PlS | P1: Plnt | Q1: Ref. Date | R1: RfTm | S1: Req. End | T1: Req. time | U1: Un | V1: B | W1: Sel. | X1: Req. Start | Y1: Req. time | Z1: ABC Ind. | AA1: FL affectd | AB1: MAT | AC1: Functional Loc.
A2: M2 | B2: 11000389 | C2: =VLOOKUP(B2,Equipment!A$1:J$575,9,0) -> E | D2: 320000018581 | E2: 120000018696 | F2: Mazak- 1 N01-01 | G2: door not open | H2: 31.08.2026 | I2: 31.08.2026 | J2: 08:25:53 | K2: 12:24:16 | L2: 0.5 | M2: 31.08.2026 | N2: 08:25:53 | O2: MCS | P2: 1041 | Q2: 31.08.2026 | R2: 12:24:16 | S2: 04.09.2026 | T2: 08:27:35 | U2: H | V2: X | Y2: 00:00:00 | Z2: A | AC2: 1041-MCS-MC
A3: M2 | B3: 11000455 | C3: =VLOOKUP(B3,Equipment!A$1:J$575,9,0) -> E | D3: 320000018580 | E3: 120000018683 | F3: Bavius TR 120-3 N01-02 | G3: TR-3 vacuum not reached | H3: 31.08.2026 | I3: 31.08.2026 | J3: 10:50:03 | K3: 12:11:00 | L3: 0.67 | M3: 31.08.2026 | N3: 10:57:03 | O3: MCS | P3: 1041 | Q3: 31.08.2026 | R3: 12:11:00 | S3: 01.09.2026 | T3: 10:50:55 | U3: H | V3: X | X3: 31.08.2026 | Y3: 10:50:55 | Z3: A | AC3: 1041-MCS-MC
A4: M2 | B4: 11000482 | C4: =VLOOKUP(B4,Equipment!A$1:J$575,9,0) -> E | D4: 320000018728 | E4: 120000018663 | F4: HURON 5 Axis Machine-2 N01-02 | G4: vacuum pressure gauge not available | H4: 31.08.2026 | I4: 31.08.2026 | J4: 09:36:46 | K4: 17:16:31 | L4: 0.9 | M4: 31.08.2026 | N4: 09:36:46 | O4: MCS | P4: 1041 | Q4: 31.08.2026 | R4: 17:16:31 | S4: 01.09.2026 | T4: 09:38:25 | U4: H | V4: X | Y4: 00:00:00 | Z4: A | AC4: 1041-MCS-MC
A5: M2 | B5: 11000206 | C5: =VLOOKUP(B5,Equipment!A$1:J$575,9,0) -> E | D5: 320000018579 | E5: 120000018685 | F5: ROUTING MACHINE 5 AXIS #6 | G5: Tool Clamp & Declamp Switch Stuck | H5: 31.08.2026 | I5: 31.08.2026 | J5: 14:00:00 | K5: 15:00:00 | L5: 1 | M5: 31.08.2026 | N5: 14:00:00 | O5: SMD | P5: 2001 | Q5: 31.08.2026 | R5: 15:00:00 | S5: 31.08.2026 | T5: 15:00:00 | U5: H | V5: X | X5: 31.08.2026 | Y5: 14:00:00 | Z5: A | AC5: 2001-SMD-RU
A6: M2 | B6: 11000322 | C6: =VLOOKUP(B6,Equipment!A$1:J$575,9,0) -> E | D6: 320000018578 | E6: 120000018673 | F6: 3 AXIS MACHINE JYOTHI HURON NX3222 NVU-C | G6: chips convayor motor overload alarm | H6: 31.08.2026 | I6: 31.08.2026 | J6: 15:10:59 | K6: 16:00:00 | L6: 0.82 | M6: 31.08.2026 | N6: 15:10:59 | O6: MSD | P6: 2001 | Q6: 31.08.2026 | R6: 16:00:00 | S6: 31.08.2026 | T6: 16:00:31 | U6: H | V6: X | X6: 31.08.2026 | Y6: 15:10:59 | Z6: A | AC6: 2001-MSD-PF
A7: M2 | B7: 11000322 | C7: =VLOOKUP(B7,Equipment!A$1:J$575,9,0) -> E | D7: 320000018584 | E7: 120000018674 | F7: 3 AXIS MACHINE JYOTHI HURON NX3222 NVU-C | G7: Chips conuyor over load | H7: 31.08.2026 | I7: 31.08.2026 | J7: 23:00:00 | K7: 23:40:00 | L7: 0.67 | M7: 31.08.2026 | N7: 23:00:00 | O7: MSD | P7: 2001 | Q7: 31.08.2026 | R7: 23:40:00 | T7: 00:00:00 | U7: H | V7: X | X7: 31.08.2026 | Y7: 22:48:48 | Z7: A | AC7: 2001-MSD-PF
A8: M2 | B8: 11000449 | C8: =VLOOKUP(B8,Equipment!A$1:J$575,9,0) -> E | D8: 320000018720 | E8: 120000018662 | F8: Bavius 2mtr-N01-02 | G8: Vacuum pressure drop in auto cycle | H8: 30.08.2026 | I8: 30.08.2026 | J8: 00:52:25 | K8: 02:20:58 | L8: 1.08 | M8: 30.08.2026 | N8: 00:52:25 | O8: MCS | P8: 1041 | Q8: 30.08.2026 | R8: 02:20:58 | S8: 31.08.2026 | T8: 00:53:14 | U8: H | V8: X | Y8: 00:00:00 | Z8: A | AC8: 1041-MCS-MC
A9: M2 | B9: 11000452 | C9: =VLOOKUP(B9,Equipment!A$1:J$575,9,0) -> E | D9: 320000018572 | E9: 120000018579 | F9: Bavius 4mtr N01-02 | G9: TCH: RUNTIME ERROR MAGAZINE FLAP CLOSED | H9: 30.08.2026 | I9: 31.08.2026 | J9: 11:04:45 | K9: 10:21:35 | L9: 2.42 | M9: 30.08.2026 | N9: 11:04:45 | O9: MCS | P9: 1041 | Q9: 31.08.2026 | R9: 10:21:35 | S9: 31.08.2026 | T9: 11:06:38 | U9: H | V9: X | Y9: 00:00:00 | Z9: A | AC9: 1041-MCS-MC
A10: M2 | B10: 11000455 | C10: =VLOOKUP(B10,Equipment!A$1:J$575,9,0) -> E | D10: 320000018721 | E10: 120000018695 | F10: Bavius TR 120-3 N01-02 | G10: motor temperature alarm generated. | H10: 30.08.2026 | I10: 30.08.2026 | J10: 21:05:14 | K10: 21:50:56 | L10: 0.5 | M10: 30.08.2026 | N10: 21:05:14 | O10: MCS | P10: 1041 | Q10: 30.08.2026 | R10: 21:50:56 | S10: 31.08.2026 | T10: 21:05:51 | U10: H | V10: X | Y10: 00:00:00 | Z10: A | AC10: 1041-MCS-MC
A11: M2 | B11: 11000493 | C11: =VLOOKUP(B11,Equipment!A$1:J$575,9,0) -> E | D11: 320000018722 | E11: 120000018682 | F11: Makino A500Z-1 N01-02 | G11: Auto operation start error maintainance | H11: 30.08.2026 | I11: 30.08.2026 | J11: 17:26:15 | K11: 18:35:49 | L11: 0.5 | M11: 30.08.2026 | N11: 17:26:15 | O11: MCS | P11: 1041 | Q11: 30.08.2026 | R11: 18:35:49 | S11: 31.08.2026 | T11: 17:28:50 | U11: H | V11: X | Y11: 00:00:00 | Z11: A | AC11: 1041-MCS-MC
A12: M2 | B12: 11000551 | C12: =VLOOKUP(B12,Equipment!A$1:J$575,9,0) -> E | D12: 320000018585 | E12: 120000018681 | F12: Breton1-Flymill-5Axis CNC | G12: c1 drive fault | H12: 29.08.2026 | I12: 29.08.2026 | J12: 13:30:16 | K12: 18:30:16 | L12: 5 | M12: 29.08.2026 | N12: 14:00:16 | O12: CWC | P12: 1031 | Q12: 29.08.2026 | R12: 18:30:16 | T12: 00:00:00 | U12: H | V12: X | X12: 29.08.2026 | Y12: 14:00:16 | Z12: A | AC12: 1031-CWC-MC
A13: M2 | B13: 11000578 | C13: =VLOOKUP(B13,Equipment!A$1:J$575,9,0) -> E | D13: 320000018586 | E13: 120000018661 | F13: JOBS-GRANSPEED 5-5 AXIS CNC | G13: X- axis bellows tension spring broken | H13: 29.08.2026 | I13: 29.08.2026 | J13: 17:20:32 | K13: 19:35:54 | L13: 2.26 | M13: 29.08.2026 | N13: 18:02:32 | O13: CWC | P13: 1031 | Q13: 29.08.2026 | R13: 19:35:54 | T13: 00:00:00 | U13: H | V13: X | X13: 29.08.2026 | Y13: 18:02:32 | Z13: A | AC13: 1031-CWC-MC
A14: M2 | B14: 11000387 | C14: =VLOOKUP(B14,Equipment!A$1:J$575,9,0) -> #N/A | D14: 320000018576 | E14: 120000018691 | F14: MSK-4 N01-01 | G14: cut coolant pressure low | H14: 29.08.2026 | I14: 31.08.2026 | J14: 09:40:55 | K14: 10:36:28 | L14: 0.48 | M14: 29.08.2026 | N14: 10:01:55 | O14: MCS | P14: 1041 | Q14: 31.08.2026 | R14: 10:36:28 | T14: 00:00:00 | U14: H | V14: X | X14: 29.08.2026 | Y14: 09:40:09 | Z14: A | AC14: 1041-MCS-MC
A15: M2 | B15: 11000388 | C15: =VLOOKUP(B15,Equipment!A$1:J$575,9,0) -> #N/A | D15: 320000018606 | E15: 120000018690 | F15: MSK-5 N01-01 | G15: cycle not start | H15: 29.08.2026 | I15: 29.08.2026 | J15: 11:00:00 | K15: 03:58:18 | L15: 1.83 | M15: 29.08.2026 | N15: 09:53:53 | O15: MCS | P15: 1041 | Q15: 29.08.2026 | R15: 03:58:18 | T15: 00:00:00 | U15: H | V15: X | X15: 29.08.2026 | Y15: 06:30:25 | Z15: A | AC15: 1041-MCS-MC
A16: M2 | B16: 11000453 | C16: =VLOOKUP(B16,Equipment!A$1:J$575,9,0) -> E | D16: 320000018603 | E16: 120000018599 | F16: Bavius TR 120-1 N01-02 | G16: C-Axis leakage | H16: 29.08.2026 | I16: 29.08.2026 | J16: 10:30:00 | K16: 03:31:11 | L16: 3.67 | M16: 29.08.2026 | N16: 07:11:54 | O16: MCS | P16: 1041 | Q16: 29.08.2026 | R16: 03:31:11 | T16: 00:00:00 | U16: H | V16: X | X16: 29.08.2026 | Y16: 07:11:54 | Z16: A | AC16: 1041-MCS-MC
A17: M2 | B17: 11000454 | C17: =VLOOKUP(B17,Equipment!A$1:J$575,9,0) -> E | D17: 320000018604 | E17: 120000018693 | F17: Bavius TR 120-2 N01-02 | G17: Handwheel blinking | H17: 29.08.2026 | I17: 29.08.2026 | J17: 12:30:00 | K17: 03:37:05 | L17: 0.33 | M17: 29.08.2026 | N17: 12:22:09 | O17: MCS | P17: 1041 | Q17: 29.08.2026 | R17: 03:37:05 | T17: 00:00:00 | U17: H | V17: X | X17: 29.08.2026 | Y17: 12:22:09 | Z17: A | AC17: 1041-MCS-MC
A18: M2 | B18: 11000455 | C18: =VLOOKUP(B18,Equipment!A$1:J$575,9,0) -> E | D18: 320000018602 | E18: 120000018576 | F18: Bavius TR 120-3 N01-02 | G18: Vacuum not reached alarm comes | H18: 29.08.2026 | I18: 29.08.2026 | J18: 03:00:00 | K18: 03:19:40 | L18: 0.67 | M18: 29.08.2026 | N18: 07:08:46 | O18: MCS | P18: 1041 | Q18: 29.08.2026 | R18: 03:19:40 | T18: 00:00:00 | U18: H | V18: X | X18: 29.08.2026 | Y18: 07:08:46 | Z18: A | AC18: 1041-MCS-MC
A19: M2 | B19: 11000208 | C19: =VLOOKUP(B19,Equipment!A$1:J$575,9,0) -> E | D19: 320000018560 | E19: 120000018670 | F19: MACHINING CENTRE 3 AXIS HAAS VF6 #8 | G19: Tool stuck into Spindle at VF6-3axis | H19: 29.08.2026 | I19: 29.08.2026 | J19: 08:00:00 | K19: 11:00:00 | L19: 3 | M19: 29.08.2026 | N19: 08:00:00 | O19: MSD | P19: 2001 | Q19: 29.08.2026 | R19: 11:00:00 | S19: 29.08.2026 | T19: 11:00:00 | U19: H | V19: X | X19: 29.08.2026 | Y19: 08:00:00 | Z19: A | AC19: 2001-MSD-PF
A20: M2 | B20: 11000227 | C20: =VLOOKUP(B20,Equipment!A$1:J$575,9,0) -> E | D20: 320000018568 | E20: 120000018577 | F20: HYDROFORM LARGE PRESS-AVURE | G20: Rubber press machine tray A not working | H20: 29.08.2026 | I20: 30.08.2026 | J20: 23:30:00 | K20: 03:00:00 | L20: 3.5 | M20: 29.08.2026 | N20: 23:30:00 | O20: SMD | P20: 2001 | Q20: 30.08.2026 | R20: 03:00:00 | T20: 00:00:00 | U20: H | V20: X | X20: 29.08.2026 | Y20: 19:43:50 | Z20: A | AC20: 2001-SMD-FR
A21: M2 | B21: 11000302 | C21: =VLOOKUP(B21,Equipment!A$1:J$575,9,0) -> E | D21: 320000018567 | E21: 120000018628 | F21: 5-AXIS DMG MORI DMC 160U-A | G21: Laser not reay | H21: 29.08.2026 | I21: 29.08.2026 | J21: 15:30:00 | K21: 19:00:00 | L21: 3.5 | M21: 29.08.2026 | N21: 15:30:00 | O21: MSD | P21: 2001 | Q21: 29.08.2026 | R21: 19:00:00 | T21: 00:00:00 | U21: H | V21: X | X21: 29.08.2026 | Y21: 13:37:29 | Z21: A | AC21: 2001-MSD-PF
A22: M2 | B22: 11000322 | C22: =VLOOKUP(B22,Equipment!A$1:J$575,9,0) -> E | D22: 320000018566 | E22: 120000018578 | F22: 3 AXIS MACHINE JYOTHI HURON NX3222 NVU-C | G22: Coolant leakage | H22: 29.08.2026 | I22: 29.08.2026 | J22: 20:00:00 | K22: 21:00:00 | L22: 1 | M22: 29.08.2026 | N22: 20:00:00 | O22: MSD | P22: 2001 | Q22: 29.08.2026 | R22: 21:00:00 | T22: 00:00:00 | U22: H | V22: X | X22: 29.08.2026 | Y22: 21:26:31 | Z22: A | AC22: 2001-MSD-PF
A23: M2 | B23: 11000576 | C23: =VLOOKUP(B23,Equipment!A$1:J$575,9,0) -> E | D23: 320000018588 | E23: 120000018595 | F23: Breton2-Eagle-5 Axis CNC | G23: nck comunication failure alarm & dada pc | H23: 28.08.2026 | I23: 28.08.2026 | J23: 02:00:35 | K23: 03:15:40 | L23: 1.25 | M23: 28.08.2026 | N23: 02:29:35 | O23: CWC | P23: 1031 | Q23: 28.08.2026 | R23: 03:15:40 | T23: 00:00:00 | U23: H | V23: X | X23: 28.08.2026 | Y23: 02:29:35 | Z23: A | AC23: 1031-CWC-MC
A24: M2 | B24: 11000578 | C24: =VLOOKUP(B24,Equipment!A$1:J$575,9,0) -> E | D24: 320000018587 | E24: 120000018598 | F24: JOBS-GRANSPEED 5-5 AXIS CNC | G24: C axis return cooling line not OK | H24: 28.08.2026 | I24: 28.08.2026 | J24: 14:15:33 | K24: 15:10:00 | L24: 0.91 | M24: 28.08.2026 | N24: 15:12:33 | O24: CWC | P24: 1031 | Q24: 29.08.2026 | R24: 15:10:00 | T24: 00:00:00 | U24: H | V24: X | X24: 28.08.2026 | Y24: 15:12:33 | Z24: A | AC24: 1031-CWC-MC
A25: M2 | B25: 11000379 | C25: =VLOOKUP(B25,Equipment!A$1:J$575,9,0) -> E | D25: 320000018657 | E25: 120000018659 | F25: HMC - H5000 2 (HMC-03) N01-01 | G25: feed automatically 0% | H25: 28.08.2026 | I25: 29.08.2026 | J25: 23:50:21 | K25: 00:10:14 | L25: 0.33 | M25: 29.08.2026 | N25: 00:32:21 | O25: MCS | P25: 1041 | Q25: 29.08.2026 | R25: 08:22:36 | S25: 30.08.2026 | T25: 00:33:52 | U25: H | V25: X | X25: 29.08.2026 | Y25: 00:33:52 | Z25: A | AC25: 1041-MCS-MC
A26: M2 | B26: 11000379 | C26: =VLOOKUP(B26,Equipment!A$1:J$575,9,0) -> E | D26: 320000018904 | E26: 120000018654 | F26: HMC - H5000 2 (HMC-03) N01-01 | G26: Y HARDWARE FAULT OF ACTIVE ENCODER | H26: 28.08.2026 | I26: 28.08.2026 | J26: 07:30:00 | K26: 04:01:37 | L26: 0.5 | M26: 28.08.2026 | N26: 07:35:05 | O26: MCS | P26: 1041 | Q26: 28.08.2026 | R26: 04:01:37 | S26: 01.09.2026 | T26: 07:36:18 | U26: H | V26: X | X26: 28.08.2026 | Y26: 07:36:18 | Z26: A | AC26: 1041-MCS-MC
A27: M2 | B27: 11000386 | C27: =VLOOKUP(B27,Equipment!A$1:J$575,9,0) -> E | D27: 320000019025 | E27: 120000018652 | F27: MSK-3 N01-01 | G27: TOOL PULL OUT | H27: 28.08.2026 | I27: 28.08.2026 | J27: 03:10:08 | K27: 11:08:27 | L27: 1 | M27: 28.08.2026 | N27: 05:27:08 | O27: MCS | P27: 1041 | Q27: 28.08.2026 | R27: 11:08:27 | S27: 29.08.2026 | T27: 05:27:46 | U27: H | V27: X | X27: 28.08.2026 | Y27: 03:10:46 | Z27: A | AC27: 1041-MCS-MC
A28: M2 | B28: 11000449 | C28: =VLOOKUP(B28,Equipment!A$1:J$575,9,0) -> E | D28: 320000018648 | E28: 120000018660 | F28: Bavius 2mtr-N01-02 | G28: pallet change issue. | H28: 28.08.2026 | I28: 28.08.2026 | J28: 12:18:51 | K28: 02:17:57 | L28: 3.35 | M28: 28.08.2026 | N28: 12:18:51 | O28: MCS | P28: 1041 | Q28: 28.08.2026 | R28: 02:17:57 | S28: 29.08.2026 | T28: 12:19:48 | U28: H | V28: X | Y28: 00:00:00 | Z28: A | AC28: 1041-MCS-MC
A29: M2 | B29: 11000454 | C29: =VLOOKUP(B29,Equipment!A$1:J$575,9,0) -> E | D29: 320000018531 | E29: 120000018627 | F29: Bavius TR 120-2 N01-02 | G29: Air pressure low alarm comes. | H29: 28.08.2026 | I29: 28.08.2026 | J29: 16:31:08 | K29: 01:40:18 | L29: 0.48 | M29: 28.08.2026 | N29: 16:31:08 | O29: MCS | P29: 1041 | Q29: 28.08.2026 | R29: 01:40:18 | S29: 29.08.2026 | T29: 16:32:11 | U29: H | V29: X | Y29: 00:00:00 | Z29: A | AC29: 1041-MCS-MC
A30: M2 | B30: 11000494 | C30: =VLOOKUP(B30,Equipment!A$1:J$575,9,0) -> E | D30: 320000018647 | E30: 120000018608 | F30: Makino A500Z-2 N01-02 | G30: abnormal sound comes in running part whi | H30: 28.08.2026 | I30: 28.08.2026 | J30: 10:00:00 | K30: 01:58:28 | L30: 8 | M30: 28.08.2026 | N30: 10:16:06 | O30: MCS | P30: 1041 | Q30: 28.08.2026 | R30: 01:58:28 | S30: 01.09.2026 | T30: 10:17:03 | U30: H | V30: X | Y30: 00:00:00 | Z30: A | AC30: 1041-MCS-MC
A31: M2 | B31: 11000227 | C31: =VLOOKUP(B31,Equipment!A$1:J$575,9,0) -> E | D31: 320000018565 | E31: 120000018626 | F31: HYDROFORM LARGE PRESS-AVURE | G31: Rubber Press machine not working | H31: 28.08.2026 | I31: 28.08.2026 | J31: 10:00:00 | K31: 20:30:00 | L31: 10.5 | M31: 28.08.2026 | N31: 10:00:00 | O31: SMD | P31: 2001 | Q31: 28.08.2026 | R31: 20:30:00 | T31: 00:00:00 | U31: H | V31: X | X31: 28.08.2026 | Y31: 10:33:07 | Z31: A | AC31: 2001-SMD-FR
A32: M2 | B32: 11000254 | C32: =VLOOKUP(B32,Equipment!A$1:J$575,9,0) -> E | D32: 320000018415 | E32: 120000018596 | F32: 3 AXIS CNC MACHINING CENTER JOBS SPEEDER | G32: spindle cooling line not ok | H32: 28.08.2026 | I32: 28.08.2026 | J32: 04:25:32 | K32: 05:00:00 | L32: 0.57 | M32: 28.08.2026 | N32: 04:25:32 | O32: MSD | P32: 2001 | Q32: 28.08.2026 | R32: 05:00:00 | T32: 00:00:00 | U32: H | V32: X | X32: 28.08.2026 | Y32: 04:25:32 | Z32: A | AC32: 2001-MSD-PF
A33: M2 | B33: 11000316 | C33: =VLOOKUP(B33,Equipment!A$1:J$575,9,0) -> E | D33: 320000018558 | E33: 120000018624 | F33: MAZAKI-500-1 Variaxis Machining Center | G33: Hydraulic unit pressure down | H33: 28.08.2026 | I33: 28.08.2026 | J33: 22:00:00 | K33: 23:30:00 | L33: 1.5 | M33: 28.08.2026 | N33: 22:00:00 | O33: AES | P33: 2001 | Q33: 28.08.2026 | R33: 23:30:00 | S33: 28.08.2026 | T33: 23:30:00 | U33: H | V33: X | X33: 28.08.2026 | Y33: 22:00:00 | Z33: A | AC33: 2001-AES-MC
A34: M2 | B34: 11000316 | C34: =VLOOKUP(B34,Equipment!A$1:J$575,9,0) -> E | D34: 320000018557 | E34: 120000018625 | F34: MAZAKI-500-1 Variaxis Machining Center | G34: tool height .2mm variation observed | H34: 28.08.2026 | I34: 28.08.2026 | J34: 14:00:00 | K34: 16:30:00 | L34: 2.5 | M34: 28.08.2026 | N34: 14:00:00 | O34: AES | P34: 2001 | Q34: 28.08.2026 | R34: 16:30:00 | S34: 28.08.2026 | T34: 16:30:00 | U34: H | V34: X | X34: 28.08.2026 | Y34: 14:00:00 | Z34: A | AC34: 2001-AES-MC
A35: M2 | B35: 11000318 | C35: =VLOOKUP(B35,Equipment!A$1:J$575,9,0) -> E | D35: 320000018556 | E35: 120000018656 | F35: DOOSAN-1 PUMA V8300MR 3 Axis VTL | G35: ATC unit air leackeage issue | H35: 28.08.2026 | I35: 28.08.2026 | J35: 09:00:00 | K35: 10:00:00 | L35: 1 | M35: 28.08.2026 | N35: 09:00:00 | O35: AES | P35: 2001 | Q35: 28.08.2026 | R35: 10:00:00 | S35: 28.08.2026 | T35: 10:00:00 | U35: H | V35: X | X35: 28.08.2026 | Y35: 09:00:00 | Z35: A | AC35: 2001-AES-TC
A36: M2 | B36: 11000322 | C36: =VLOOKUP(B36,Equipment!A$1:J$575,9,0) -> E | D36: 320000018555 | E36: 120000018609 | F36: 3 AXIS MACHINE JYOTHI HURON NX3222 NVU-C | G36: Axis SP1 drive fault | H36: 28.08.2026 | I36: 28.08.2026 | J36: 21:00:00 | K36: 22:00:00 | L36: 1 | M36: 28.08.2026 | N36: 21:00:00 | O36: MSD | P36: 2001 | Q36: 28.08.2026 | R36: 22:00:00 | S36: 28.08.2026 | T36: 22:00:01 | U36: H | V36: X | X36: 28.08.2026 | Y36: 21:00:00 | Z36: A | AC36: 2001-MSD-PF
A37: M2 | B37: 11000327 | C37: =VLOOKUP(B37,Equipment!A$1:J$575,9,0) -> E | D37: 320000018554 | E37: 120000018597 | F37: 3-AXIS VMC RDX20(JYOTI) | G37: SPINDLE CHILLR NOT ON ALARAM | H37: 28.08.2026 | I37: 28.08.2026 | J37: 15:00:00 | K37: 16:00:00 | L37: 1 | M37: 28.08.2026 | N37: 15:00:00 | O37: MSD | P37: 2001 | Q37: 28.08.2026 | R37: 16:00:00 | S37: 28.08.2026 | T37: 16:00:00 | U37: H | V37: X | X37: 28.08.2026 | Y37: 15:00:00 | Z37: A | AC37: 2001-MSD-GC
A38: M2 | B38: 11000380 | C38: =VLOOKUP(B38,Equipment!A$1:J$575,9,0) -> E | D38: 320000018704 | E38: 120000018640 | F38: HMC - H5000 3 (HMC 4) N01-01 | G38: tool change door not open | H38: 27.08.2026 | I38: 03.09.2026 | J38: 11:27:33 | K38: 12:18:44 | L38: 48.04 | M38: 27.08.2026 | N38: 11:27:33 | O38: MCS | P38: 1041 | Q38: 03.09.2026 | R38: 12:18:44 | S38: 31.08.2026 | T38: 11:30:07 | U38: H | V38: X | Y38: 00:00:00 | Z38: A | AC38: 1041-MCS-MC
A39: M2 | B39: 11000382 | C39: =VLOOKUP(B39,Equipment!A$1:J$575,9,0) -> E | D39: 320000018443 | E39: 120000018637 | F39: HMC - H5000 (HMC 6)(N01-01) | G39: atc cylinder leakage | H39: 27.08.2026 | I39: 27.08.2026 | J39: 04:40:41 | K39: 11:50:14 | L39: 7.16 | M39: 27.08.2026 | N39: 04:40:41 | O39: MCS | P39: 1041 | Q39: 27.08.2026 | R39: 02:31:41 | S39: 31.08.2026 | T39: 04:42:21 | U39: H | V39: X | Y39: 00:00:00 | Z39: A | AC39: 1041-MCS-MC
A40: M2 | B40: 11000384 | C40: =VLOOKUP(B40,Equipment!A$1:J$575,9,0) -> E | D40: 320000018488 | E40: 120000018639 | F40: MSK-1 N01-01 | G40: COOLANT PRESSURE NOT PROPER | H40: 27.08.2026 | I40: 27.08.2026 | J40: 09:30:00 | K40: 14:24:27 | L40: 0.83 | M40: 27.08.2026 | N40: 08:39:49 | O40: MCS | P40: 1041 | Q40: 27.08.2026 | R40: 14:24:27 | S40: 31.08.2026 | T40: 08:40:56 | U40: H | V40: X | Y40: 00:00:00 | Z40: A | AC40: 1041-MCS-MC
...

Sheet Equipment
A1: Equipment | B1: Description | C1: ABC Ind. | D1: Manufacturer of Asset | E1: Manufacturer's Serial Number | F1: Model number | G1: UserStatus | H1: SysStatus | I1: C | J1: Plnt
A2: 11000000 | B2: 5T EOT CRANE-1 | C2: A | D2: KONE CRANES | E2: KS 0311 | F2: 5t | H2: INST | I2: E | J2: 1001
A3: 11000001 | B3: COMPRESSION RIVETING MACHINE_EA COLD | C3: A | D3: US INDUSTRIAL TOOLS LTD | E3: 12091 | F3: US150EA-COLD | H3: INST | I3: E | J3: 1001
A4: 11000005 | B4: PAINT BOOTH-1 | C4: A | D4: TAL | E4: 85000 CFM ASU | F4: 85000 CFM ASU | H4: INST | I4: E | J4: 1001
A5: 11000006 | B5: CHILLER PLANT - 100TR FOR PAINT BOOTH | C5: A | D5: VOLTAS | E5: D000039 | F5: GSWCDXR1001-1 | H5: INST | I5: E | J5: 1001
A6: 11000007 | B6: LATHE MACHINE | C6: A | D6: ESTEAM | E6: 030085 | F6: ETM 410 x 1000 | H6: INST | I6: E | J6: 1001
A7: 11000008 | B7: CYLINDRICAL GRINDING MACHINE | C7: A | D7: SOLCO | E7: 1089 | F7: CMTU 1000 / 150 | H7: INST | I7: E | J7: 1001
A8: 11000009 | B8: VERTICAL MILLING MACHINE | C8: A | D8: ESTEAM | E8: 4KS | F8: 4KS | H8: INST | I8: E | J8: 1001
A9: 11000015 | B9: 5T EOT CRANE-3 | C9: A | D9: KONE CRANES | E9: KS001629 | F9: 5t | H9: INST | I9: E | J9: 1001
A10: 11000019 | B10: 5T EOT CRANE-2 | C10: A | D10: KONE CRANES | E10: KS001577 | F10: 5t | H10: INST | I10: E | J10: 1001
A11: 11000020 | B11: PAINT BOOTH-2 | C11: A | D11: PRISM SURFACE COATINGS | E11: 100962 | F11: HMX57K | H11: INST | I11: E | J11: 1001
A12: 11000021 | B12: CPC PAINT BOOTH (PLANT-3) | C12: A | D12: PRISM | E12: D000008 | F12: ACEGADXR1001MZ | H12: INST | I12: E | J12: 1001
A13: 11000022 | B13: CHILLER UNIT ( PLANT-3) | C13: A | D13: VOLTAS | E13: D000008 | F13: ACEGADXR1001MZ | H13: INST | I13: E | J13: 1001
... A17: 11000036 | B17: WING FUEL LEAK TESTING EQUIPMENT_EXXSOL | C17: A | D17: SOORI HYDRAULICS | E17: SOORI HYDRAULICS | F17: SOORI HYDRAULICS | H17: INST | I17: E | J17: 1001
A18: 11000043 | B18: SPRAY BOOTH CUM OVEN (BTO) | C18: A | D18: TAKISHA | H18: INST | I18: E | J18: 2501
A19: 11000044 | B19: SPRAY BOOTH (BTT) | C19: A | D19: TAKISHA | H19: INST | I19: E | J19: 2501
A20: 11000049 | B20: DOT PEEN MAKING | C20: A | D20: SIC Marking | F20: EC1 | H20: INST | I20: E | J20: 2501
A21: 11000052 | B21: Flap Peening Machine | C21: A | D21: SHOCKFORM | E21: PRO-3708 | F21: FPK-PRO-102-90 | H21: INST | I21: E | J21: 2501
A22: 11000053 | B22: 3T EOT CRANE -1 | C22: A | D22: KONECRANES | E22: 200760061/20 | F22: KS002016​ | H22: INST | I22: E | J22: 2501
A23: 11000054 | B23: 3T EOT CRANE -2 | C23: A | D23: KONECRANES | E23: 200760062/20 | F23: KS002017 | H23: INST | I23: E | J23: 2501
A24: 11000055 | B24: 3T EOT CRANE -3 | C24: A | D24: KONECRANES | E24: 200760063/20 | F24: KS002018 | H24: INST | I24: E | J24: 2501
A25: 11000056 | B25: FUME EXTRANCTION SYSTEM | C25: A | D25: WHITENAIR TECHNOLOGIES | H25: INST | I25: E | J25: 2501
A26: 11000057 | B26: 6.3T EOT CRANE -1 | C26: A | D26: Spark line | E26: DGE0T20006300234 | F26: STAHL | H26: INST | I26: E | J26: 2501
A27: 11000058 | B27: 6.3T EOT CRANE -2 | C27: A | D27: Spark line | E27: DGE0T20006300235 | F27: STAHL | H27: INST | I27: E | J27: 2501
A28: 11000069 | B28: DIMPLING MACHINE 1 | C28: A | D28: US Industrial Tools | E28: 92011.2 | F28: US150EA-Hot | H28: INST | I28: E | J28: 1501
A29: 11000070 | B29: DIMPLING MACHINE 2 | C29: A | D29: US Industrial Tools | E29: 92011.1 | F29: US150EA-Hot | H29: INST | I29: E | J29: 1501
A30: 11000071 | B30: COMPRESSION RIVETER M/C 1 | C30: A | D30: US Industrial Tools | E30: 9110.1 | F30: US150EA | H30: INST | I30: E | J30: 1501
A31: 11000072 | B31: COMPRESSION RIVETER M/C 2 | C31: A | D31: US Industrial Tools | E31: 9110.2 | F31: US150EA | H31: INST | I31: E | J31: 1501
A32: 11000091 | B32: COMPRESSION RIVETER SMALL 150-12 | C32: A | D32: US industrial | E32: NIL | F32: US 150-12 | H32: INST | I32: E | J32: 1501
A33: 11000093 | B33: HOT OVEN-1 | C33: A | D33: NOT AVAILABLE | E33: NOT AVAILABLE | F33: NOT AVAILABLE | H33: INST | I33: E | J33: 1501
A34: 11000094 | B34: SALT SPRAY APPARATUS | C34: A | D34: KIRAN TEST MEASURES | E34: KIRAN TEST MEASURES | F34: KIRAN TEST MEASURES | H34: INST | I34: E | J34: 1501
A35: 11000095 | B35: AUTOCLAVE | C35: A | D35: Scholz | E35: 47233 | F35: D-48653 | H35: INST | I35: E | J35: 1501
A36: 11000113 | B36: PAA_ TRANSPORTER | C36: A | D36: SEW | E36: NIL | F36: NIL | H36: INST | I36: E | J36: 1501
A37: 11000131 | B37: PAA_ELECTRICAL PANEL | C37: A | D37: Square mag | E37: NIL | F37: Nil | H37: INST | I37: E | J37: 1501
... A41: 11000182 | B41: C-SCAN_OLD_QC ROOM | C41: A | D41: C-Scan( VIVACE Sonic PVT Ltd | E41: 53772 | F41: SOFG-UT | H41: INST | I41: E | J41: 1501
A42: 11000203 | B42: WATER JET CUTTING MACHINE-FLOW | C42: A | D42: FLOW | E42: 120478 | F42: MACH2B | G42: EACT | H42: INST | I42: E | J42: 2001
A43: 11000204 | B43: ROUTING MACHINE 3 AXIS #1 | C43: A | D43: THERMWOOD | E43: C533290907 | F43: C53 | G43: EACT | H43: INST | I43: E | J43: 2001
A44: 11000205 | B44: 5 AXIS CNC NIBBLE/PUNCH PRESS | C44: A | D44: TRUMPF | E44: TP0042 | F44: TRUPUNCH 5000 | G44: EACT | H44: INST | I44: E | J44: 2001
A45: 11000206 | B45: ROUTING MACHINE 5 AXIS #6 | C45: A | D45: THERMWOOD | E45: C67DT35550805 | F45: M67 55DT | G45: EACT | H45: INST | I45: E | J45: 2001
A46: 11000208 | B46: MACHINING CENTRE 3 AXIS HAAS VF6 #8 | C46: A | D46: HAAS | E46: 20873 | F46: VF6 | G46: EACT | H46: INST | I46: E | J46: 2001
...

Sheet Available Hours (DP)
A3: Months | B3: 46113 | C3: 46143 | D3: 46174 | E3: 46204 | F3: 46235 | G3: 46266 | H3: 46296 | I3: 46327 | J3: 46357 | K3: 46388 | L3: 46419 | M3: 46447
A4: Shift Hours | B4: 8 | C4: 8 | D4: 8 | E4: 8 | F4: 8 | G4: 8 | H4: 8 | I4: 8 | J4: 8 | K4: 8 | L4: 8 | M4: 8
A5: No. of Shifts | B5: 3 | C5: 3 | D5: 3 | E5: 3 | F5: 3 | G5: 3 | H5: 3 | I5: 3 | J5: 3 | K5: 3 | L5: 3 | M5: 3
A6: Lunch Break + Dinner Break + Tea Break | B6: 0 | C6: 0 | D6: 0 | E6: 0 | F6: 0 | G6: 0 | H6: 0 | I6: 0 | J6: 0 | K6: 0 | L6: 0 | M6: 0
A7: Shift Overlap | B7: 0 | C7: 0 | D7: 0 | E7: 0 | F7: 0 | G7: 0 | H7: 0 | I7: 0 | J7: 0 | K7: 0 | L7: 0 | M7: 0
A8: Total | B8: 0 | C8: 0 | D8: 0 | E8: 0 | F8: 0 | G8: 0 | H8: 0 | I8: 0 | J8: 0 | K8: 0 | L8: 0 | M8: 0
A9: Total available hours for production in a day | B9: 24 | C9: 24 | D9: 24 | E9: 24 | F9: 24 | G9: 24 | H9: 24 | I9: 24 | J9: 24 | K9: 24 | L9: 24 | M9: 24
A10: Total operating days in a month | B10: 30 | C10: 31 | D10: 30 | E10: 31 | F10: 31 | G10: 30 | H10: 31 | I10: 30 | J10: 31 | K10: 31 | L10: 28 | M10: 31
A11: Total available hours in a month | B11: 720 | C11: 744 | D11: 720 | E11: 744 | F11: 744 | G11: 720 | H11: 744 | I11: 720 | J11: 744 | K11: 744 | L11: 672 | M11: 744

Sheet Available Hours (Assy)
A3: Months | B3: 46113 | C3: 46143 | D3: 46174 | E3: 46204 | F3: 46235 | G3: 46266 | H3: 46296 | I3: 46327 | J3: 46357 | K3: 46388 | L3: 46419 | M3: 46447
A4: Shift Hours | B4: 8 | C4: 8 | D4: 8 | E4: 8 | F4: 8 | G4: 8 | H4: 8 | I4: 8 | J4: 8 | K4: 8 | L4: 8 | M4: 8
A5: No. of Shifts | B5: 2 | C5: 2 | D5: 2 | E5: 2 | F5: 2 | G5: 2 | H5: 2 | I5: 2 | J5: 2 | K5: 2 | L5: 2 | M5: 2
A6: Lunch Break + Dinner Break + Tea Break | B6: 2 | C6: 2 | D6: 2 | E6: 2 | F6: 2 | G6: 2 | H6: 2 | I6: 2 | J6: 2 | K6: 2 | L6: 2 | M6: 2
A7: Shift Overlap | B7: 0.5 | C7: 0.5 | D7: 0.5 | E7: 0.5 | F7: 0.5 | G7: 0.5 | H7: 0.5 | I7: 0.5 | J7: 0.5 | K7: 0.5 | L7: 0.5 | M7: 0.5
A8: Total | B8: 2.5 | C8: 2.5 | D8: 2.5 | E8: 2.5 | F8: 2.5 | G8: 2.5 | H8: 2.5 | I8: 2.5 | J8: 2.5 | K8: 2.5 | L8: 2.5 | M8: 2.5
A9: Total available hours for production in a day | B9: 13.5 | C9: 13.5 | D9: 13.5 | E9: 13.5 | F9: 13.5 | G9: 13.5 | H9: 13.5 | I9: 13.5 | J9: 13.5 | K9: 13.5 | L9: 13.5 | M9: 13.5
A10: Total operating days in a month | B10: 30 | C10: 31 | D10: 30 | E10: 31 | F10: 31 | G10: 30 | H10: 31 | I10: 30 | J10: 31 | K10: 31 | L10: 28 | M10: 31
A11: Total available hours in a month | B11: 405 | C11: 418.5 | D11: 405 | E11: 418.5 | F11: 418.5 | G11: 405 | H11: 418.5 | I11: 405 | J11: 418.5 | K11: 418.5 | L11: 378 | M11: 418.5

Sheet PM Orders
A1: Order | B1: Equipment | C1: Equipment Category | D1: Description of technical object | E1: PlPl | F1: Maint. item text | G1: PlS | H1: Strat. | I1: Start date | J1: Plnd. date | K1: Completion | L1: Cost Ctr | M1: ABC Ind. | N1: Type | O1: Material | P1: Call No. | Q1: CoCd | R1: Location | S1: Plnt | T1: Work Ctr
A2: 330000051470 | B2: 11000093 | C2: =VLOOKUP(B2,Equipment!A$1:J$470,9,0) -> E | D2: HOT OVEN-1 | E2: 1501 | F2: Monthly PM | G2: QTY | I2: 01.08.2026 | J2: 01.08.2026 | K2: 01.08.2026 | L2: L201010043 | M2: A | N2: PM03 | P2: 38 | Q2: 1500 | R2: QC LAB | S2: 1501 | T2: TLMALPEM
A3: 330000051471 | B3: 11000094 | C3: =VLOOKUP(B3,Equipment!A$1:J$470,9,0) -> E | D3: SALT SPRAY APPARATUS | E3: 1501 | F3: Monthly PM | G3: QTY | I3: 01.08.2026 | J3: 01.08.2026 | K3: 01.08.2026 | L3: L201010043 | M3: A | N3: PM03 | P3: 37 | Q3: 1500 | R3: QC LAB | S3: 1501 | T3: TLMALPEM
A4: 330000051061 | B4: 11000229 | C4: =VLOOKUP(B4,Equipment!A$1:J$470,9,0) -> E | D4: NC PIPE BENDING MACHINE-EATON LEONARD | E4: 2001 | F4: QUARTERLY PREVENTIVE MAINTENANCE | G4: TSD | H4: MONTH | I4: 01.08.2026 | J4: 01.08.2026 | K4: 01.08.2026 | L4: S302011604 | M4: A | N4: PM03 | P4: 16 | Q4: 2000 | R4: TUBE BEND | S4: 2001 | T4: TS-03-01
A5: 330000051474 | B5: 11000229 | C5: =VLOOKUP(B5,Equipment!A$1:J$470,9,0) -> E | D5: NC PIPE BENDING MACHINE-EATON LEONARD | E5: 2001 | F5: MONTHLY PREVENTIVE MAINTENANCE | G5: TSD | H5: MONTH | I5: 01.08.2026 | J5: 01.08.2026 | K5: 01.08.2026 | L5: S302011604 | M5: A | N5: PM03 | P5: 47 | Q5: 2000 | R5: TUBE BEND | S5: 2001 | T5: TS-03-01
A6: 330000051476 | B6: 11000255 | C6: =VLOOKUP(B6,Equipment!A$1:J$470,9,0) -> E | D6: 5 AXIS CNC MACHINING CENTER JOBS EVER7 | E6: 2001 | F6: MONTHLY PREVENTIVE MAINTENANCE | G6: MSD | H6: MONTH | I6: 01.08.2026 | J6: 01.08.2026 | K6: 01.08.2026 | L6: S304011811 | M6: A | N6: PM03 | P6: 48 | Q6: 2000 | R6: M/C LINE-1 | S6: 2001 | T6: MS-03-03
A7: 330000051064 | B7: 11000255 | C7: =VLOOKUP(B7,Equipment!A$1:J$470,9,0) -> E | D7: 5 AXIS CNC MACHINING CENTER JOBS EVER7 | E7: 2001 | F7: QUARTERLY PREVENTIVE MAINTENANCE | G7: MSD | H7: MONTH | I7: 01.08.2026 | J7: 01.08.2026 | K7: 01.08.2026 | L7: S304011811 | M7: A | N7: PM03 | P7: 18 | Q7: 2000 | R7: M/C LINE-1 | S7: 2001 | T7: MS-03-03
A8: 330000051479 | B8: 11000315 | C8: =VLOOKUP(B8,Equipment!A$1:J$470,9,0) -> E | D8: 4-AXIS CNC ROUTER-FLEXICAM | E8: 2001 | F8: MONTHLY PREVENTIVE MAINTENANCE | G8: SMD | H8: MONTH | I8: 01.08.2026 | J8: 01.08.2026 | K8: 01.08.2026 | L8: S204010026 | M8: A | N8: PM03 | P8: 47 | Q8: 2000 | R8: ROUTNGLINE | S8: 2001 | T8: SM-01-05
A9: 330000050379 | B9: 11000315 | C9: =VLOOKUP(B9,Equipment!A$1:J$470,9,0) -> E | D9: 4-AXIS CNC ROUTER-FLEXICAM | E9: 2001 | F9: HALF YEARLY PREVENTIVE MAINTENANCE | G9: SMD | H9: MONTH | I9: 01.08.2026 | J9: 01.08.2026 | K9: 01.08.2026 | L9: S204010026 | M9: A | N9: PM03 | P9: 8 | Q9: 2000 | R9: ROUTNGLINE | S9: 2001 | T9: SM-01-05
A10: 330000049044 | B10: 11000315 | C10: =VLOOKUP(B10,Equipment!A$1:J$470,9,0) -> E | D10: 4-AXIS CNC ROUTER-FLEXICAM | E10: 2001 | F10: YEARLY PREVENTIVE MAINTENANCE | G10: SMD | H10: MONTH | I10: 01.08.2026 | J10: 01.08.2026 | K10: 01.08.2026 | L10: S204010026 | M10: A | N10: PM03 | P10: 4 | Q10: 2000 | R10: ROUTNGLINE | S10: 2001 | T10: SM-01-05
A11: 330000051380 | B11: 11000325 | C11: =VLOOKUP(B11,Equipment!A$1:J$470,9,0) -> E | D11: 5-AXIS HAAS UMC 750 -A | E11: 2001 | F11: QUARTERLY PREVENTIVE MAINTENANCE | G11: MSD | H11: MONTH | I11: 01.08.2026 | J11: 01.08.2026 | K11: 01.08.2026 | L11: S304011831 | M11: A | N11: PM03 | P11: 16 | Q11: 2000 | R11: M/C LINE-5 | S11: 2001 | T11: MS-03-11
A12: 330000051066 | B12: 11000325 | C12: =VLOOKUP(B12,Equipment!A$1:J$470,9,0) -> E | D12: 5-AXIS HAAS UMC 750 -A | E12: 2001 | F12: HALF YEARLY PREVENTIVE MAINTENANCE | G12: MSD | H12: MONTH | I12: 01.08.2026 | J12: 01.08.2026 | K12: 01.08.2026 | L12: S304011831 | M12: A | N12: PM03 | P12: 8 | Q12: 2000 | R12: M/C LINE-5 | S12: 2001 | T12: MS-03-11
A13: 330000051067 | B13: 11000326 | C13: =VLOOKUP(B13,Equipment!A$1:J$470,9,0) -> E | D13: TURN MILL AX-200 (JYOTI ) | E13: 2001 | F13: HALF YEARLY PREVENTIVE MAINTENANCE | G13: MSD | H13: MONTH | I13: 01.08.2026 | J13: 01.08.2026 | K13: 01.08.2026 | L13: S304011832 | M13: A | N13: PM03 | P13: 8 | Q13: 2000 | R13: M/C LINE-3 | S13: 2001 | T13: MS-03-12
A14: 330000050380 | B14: 11000326 | C14: =VLOOKUP(B14,Equipment!A$1:J$470,9,0) -> E | D14: TURN MILL AX-200 (JYOTI ) | E14: 2001 | F14: YEARLY PREVENTIVE MAINTENANCE | G14: MSD | H14: MONTH | I14: 01.08.2026 | J14: 01.08.2026 | K14: 01.08.2026 | L14: S304011832 | M14: A | N14: PM03 | P14: 4 | Q14: 2000 | R14: M/C LINE-3 | S14: 2001 | T14: MS-03-12
A15: 330000051381 | B15: 11000326 | C15: =VLOOKUP(B15,Equipment!A$1:J$470,9,0) -> E | D15: TURN MILL AX-200 (JYOTI ) | E15: 2001 | F15: QUARTERLY PREVENTIVE MAINTENANCE | G15: MSD | H15: MONTH | I15: 01.08.2026 | J15: 01.08.2026 | K15: 01.08.2026 | L15: S304011832 | M15: A | N15: PM03 | P15: 16 | Q15: 2000 | R15: M/C LINE-3 | S15: 2001 | T15: MS-03-12
... A18: 330000051461 | B18: 11000493 | C18: =VLOOKUP(B18,Equipment!A$1:J$470,9,0) -> E | D18: Makino A500Z-1 N01-02 | E18: 1041 | F18: Monthly Prev. Maint. For Makino1 | G18: MCS | H18: MONTH | I18: 01.08.2026 | J18: 01.08.2026 | K18: 02.08.2026 | L18: A304110215 | M18: A | N18: PM03 | P18: 47 | Q18: 1000 | R18: M/C SHOP 2 | S18: 1041 | T18: 1119
A19: 330000051040 | B19: 11000548 | C19: =VLOOKUP(B19,Equipment!A$1:J$470,9,0) -> E | D19: LECTRA-1-Prepreg Cutting | E19: 1031 | F19: QUARTERLY PREV MAINT FOR 103120000020 | G19: CWC | H19: MONTH | I19: 01.08.2026 | J19: 01.08.2026 | L19: A303081723 | M19: A | N19: PM03 | P19: 16 | Q19: 1000 | R19: CNC | S19: 1031 | T19: LECTRA 1
A20: 330000051404 | B20: 11001307 | C20: =VLOOKUP(B20,Equipment!A$1:J$470,9,0) -> E | D20: PUMA V8300-7 | E20: 1002 | F20: Preventive Maintenance plan | G20: MSH | H20: MONTH | I20: 01.08.2026 | J20: 01.08.2026 | K20: 01.08.2026 | M20: A | N20: PM03 | P20: 1 | Q20: 1000 | R20: BAY1 | S20: 1002
A21: 330000051436 | B21: 11001390 | C21: =VLOOKUP(B21,Equipment!A$1:J$470,9,0) -> E | D21: DOOSAN - Puma SMX5100XL | E21: 1002 | F21: DOOSAN-01-Bay3-Preventive Maint-11001390 | G21: MNT | H21: MONTH | I21: 01.08.2026 | J21: 01.08.2026 | K21: 01.08.2026 | L21: A102023200 | M21: A | N21: PM03 | P21: 4 | Q21: 1000 | R21: SAF-MACH | S21: 1002 | T21: TCOE_PEM
A22: 330000051481 | B22: 21000085 | C22: =VLOOKUP(B22,Equipment!A$1:J$470,9,0) -> U | D22: HVAC-1 | E22: 2501 | F22: MONTHLY PM CHECK FOR HVAC-1 | G22: ASS | H22: MONTH | I22: 01.08.2026 | J22: 01.08.2026 | K22: 01.08.2026 | L22: B401010004 | M22: A | N22: PM03 | P22: 48 | Q22: 2500 | R22: SHOP FLR-1 | S22: 2501 | T22: FIN1-1
A23: 330000051482 | B23: 21000102 | C23: =VLOOKUP(B23,Equipment!A$1:J$470,9,0) -> U | D23: HVAC-5 | E23: 2501 | F23: MONTHLY PM CHECK FOR HVAC-5 | G23: ASS | H23: MONTH | I23: 01.08.2026 | J23: 01.08.2026 | K23: 01.08.2026 | L23: B401010004 | M23: A | N23: PM03 | P23: 47 | Q23: 2500 | R23: SHOP FLR-2 | S23: 2501 | T23: VFPOS5
A24: 330000048997 | B24: 21000185 | C24: =VLOOKUP(B24,Equipment!A$1:J$470,9,0) -> #N/A | D24: AIR COMPRESSOR - 5 | E24: 1501 | F24: YEARLY PREV MAINT | G24: OUL | H24: MONTH | I24: 01.08.2026 | J24: 01.08.2026 | K24: 01.08.2026 | L24: L201010043 | M24: A | N24: PM03 | P24: 4 | Q24: 1500 | R24: UTILIBUILD | S24: 1501 | T24: TLMALPEM
B25: 21000767 | C25: =VLOOKUP(B25,Equipment!A$1:J$470,9,0) -> #N/A | D25: DG Set-3-500 KVA-CUMMINS | E25: 1031 | F25: AMC For DG 03 500KVA | G25: UTL | I25: 01.08.2026 | J25: 01.08.2026 | L25: A303081701 | M25: A | N25: PM03 | P25: 9 | Q25: 1000 | R25: SWITCHGEAR | S25: 1031 | T25: TASL_PEM
B26: 21000769 | C26: =VLOOKUP(B26,Equipment!A$1:J$470,9,0) -> #N/A | D26: DG Set-5-1500 KVA-CUMMINS | E26: 1031 | F26: AMC For DG 05 1500 KVA | G26: UTL | I26: 01.08.2026 | J26: 01.08.2026 | L26: A303081701 | M26: A | N26: PM03 | P26: 9 | Q26: 1000 | R26: SWITCHGEAR | S26: 1031 | T26: TASL_PEM
B27: 21000770 | C27: =VLOOKUP(B27,Equipment!A$1:J$470,9,0) -> #N/A | D27: DG Set-6-1500 KVA-CUMMINS | E27: 1031 | F27: AMC For DG 06 1500 KVA | G27: UTL | I27: 01.08.2026 | J27: 01.08.2026 | L27: A303081701 | M27: A | N27: PM03 | P27: 9 | Q27: 1000 | R27: SWITCHGEAR | S27: 1031 | T27: TASL_PEM
B28: 21000911 | C28: =VLOOKUP(B28,Equipment!A$1:J$470,9,0) -> #N/A | D28: DG Set-7;1010 KVA;CUMMINS | E28: 1031 | F28: AMC For DG 07 1010 KVA | G28: UTL | I28: 01.08.2026 | J28: 01.08.2026 | L28: A303081707 | M28: A | N28: PM03 | P28: 9 | Q28: 1000 | R28: DG | S28: 1031 | T28: TASL_PEM
A29: 330000051384 | B29: 11000005 | C29: =VLOOKUP(B29,Equipment!A$1:J$470,9,0) -> E | D29: PAINT BOOTH-1 | E29: 1001 | F29: MONTHLY PREVENTIVE MAINTENANCE | G29: PL1 | H29: MONTH | I29: 02.08.2026 | J29: 02.08.2026 | K29: 02.08.2026 | L29: A201010143 | M29: A | N29: PM03 | P29: 47 | Q29: 1000 | R29: PAINTING | S29: 1001 | T29: TASLMANT
A30: 330000051646 | B30: 11000325 | C30: =VLOOKUP(B30,Equipment!A$1:J$470,9,0) -> E | D30: 5-AXIS HAAS UMC 750 -A | E30: 2001 | F30: MONTHLY PREVENTIVE MAINTENANCE | G30: MSD | H30: MONTH | I30: 02.08.2026 | J30: 02.08.2026 | K30: 02.08.2026 | L30: S304011831 | M30: A | N30: PM03 | P30: 51 | Q30: 2000 | R30: M/C LINE-5 | S30: 2001 | T30: MS-03-11
A31: 330000051647 | B31: 11000333 | C31: =VLOOKUP(B31,Equipment!A$1:J$470,9,0) -> E | D31: 5-AXIS DMG MORI DMC 160U-B | E31: 2001 | F31: MONTHLY PREVENTIVE MAINTENANCE | G31: MSD | H31: MONTH | I31: 02.08.2026 | J31: 02.08.2026 | K31: 02.08.2026 | L31: S304011834 | M31: A | N31: PM03 | P31: 47 | Q31: 2000 | R31: M/C LINE-2 | S31: 2001 | T31: MS-03-13
A32: 330000051489 | B32: 11000439 | C32: =VLOOKUP(B32,Equipment!A$1:J$470,9,0) -> E | D32: HMC-Heller-HF3500 (HMC 8) N01-01 | E32: 1041 | F32: Monthly Prev. Maint. for Heller-HF3500 | G32: MCS | H32: MONTH | I32: 02.08.2026 | J32: 02.08.2026 | K32: 03.08.2026 | L32: A304111201 | M32: A | N32: PM03 | P32: 47 | Q32: 1000 | R32: M/C SHOP-1 | S32: 1041 | T32: MTP013
A33: 330000051649 | B33: 11001386 | C33: =VLOOKUP(B33,Equipment!A$1:J$470,9,0) -> E | D33: HAAS UMC 750-B | E33: 2001 | F33: MONTHLY PREVENTIVE MAINTENANCE | G33: MSD | I33: 02.08.2026 | J33: 02.08.2026 | K33: 02.08.2026 | L33: S304011852 | M33: A | N33: PM03 | P33: 7 | Q33: 2000 | R33: MSD | S33: 2001 | T33: MS-03-18
A34: 330000051513 | B34: 21000184 | C34: =VLOOKUP(B34,Equipment!A$1:J$470,9,0) -> #N/A | D34: AIR COMPRESSOR -6_CAPACITY - 275 CFM | E34: 1501 | F34: MONTHLY PREV MAINT | G34: OUL | H34: MONTH | I34: 02.08.2026 | J34: 02.08.2026 | K34: 02.08.2026 | L34: L201010043 | M34: A | N34: PM03 | P34: 48 | Q34: 1500 | R34: UTILIBUILD | S34: 1501 | T34: TLMALPEM
A35: 330000051484 | B35: 21000975 | C35: =VLOOKUP(B35,Equipment!A$1:J$470,9,0) -> #N/A | D35: EOT CRANE - 2 | E35: 1004 | F35: MONTHLY_PM_EOT CRANE - 2 | G35: MNT | H35: MONTH | I35: 10.08.2026 | J35: 02.08.2026 | K35: 03.08.2026 | L35: A201271843 | M35: A | N35: PM03 | P35: 28 | Q35: 1000 | R35: BY2 | S35: 1004 | T35: H07PEM
A36: 330000051287 | B36: 11000015 | C36: =VLOOKUP(B36,Equipment!A$1:J$470,9,0) -> E | D36: 5T EOT CRANE-3 | E36: 1001 | F36: MONTHLY PREVENTIVE MAINTENANCE | G36: PL3 | H36: MONTH | I36: 03.08.2026 | J36: 03.08.2026 | K36: 03.08.2026 | L36: A201010743 | M36: A | N36: PM03 | P36: 47 | Q36: 1000 | R36: ASSY | S36: 1001 | T36: TASLMANT
A37: 330000051677 | B37: 11000326 | C37: =VLOOKUP(B37,Equipment!A$1:J$470,9,0) -> E | D37: TURN MILL AX-200 (JYOTI ) | E37: 2001 | F37: MONTHLY PREVENTIVE MAINTENANCE | G37: MSD | H37: MONTH | I37: 03.08.2026 | J37: 03.08.2026 | K37: 03.08.2026 | L37: S304011832 | M37: A | N37: PM03 | P37: 47 | Q37: 2000 | R37: M/C LINE-3 | S37: 2001 | T37: MS-03-12
A38: 330000051379 | B38: 11000380 | C38: =VLOOKUP(B38,Equipment!A$1:J$470,9,0) -> E | D38: HMC - H5000 3 (HMC 4) N01-01 | E38: 1041 | F38: Monthly Prev. Maint. for HMC - H5000 3 | G38: MCS | H38: MONTH | I38: 03.08.2026 | J38: 03.08.2026 | K38: 05.08.2026 | L38: A303110107 | M38: A | N38: PM03 | P38: 55 | Q38: 1000 | R38: M/C SHOP-1 | S38: 1041 | T38: 1202
A39: 330000051241 | B39: 11000814 | C39: =VLOOKUP(B39,Equipment!A$1:J$470,9,0) -> E | D39: Mazak- Variaxis C 600-4 | E39: 1002 | F39: PREV MAINT PLAN 11000814 | G39: MSD | H39: MONTH | I39: 03.08.2026 | J39: 03.08.2026 | K39: 03.08.2026 | L39: A302021141 | M39: A | N39: PM03 | P39: 18 | Q39: 1000 | R39: BAY 2 | S39: 1002 | T39: MZK-C600
A40: 330000051243 | B40: 11000823 | C40: =VLOOKUP(B40,Equipment!A$1:J$470,9,0) -> E | D40: Mazak Integrex i-630V-08 | E40: 1002 | F40: Bi Monthly Prev maintenance plan | G40: MSD | H40: MONTH | I40: 03.08.2026 | J40: 03.08.2026 | K40: 03.08.2026 | L40: A302021141 | M40: A | N40: PM03 | P40: 14 | Q40: 1000 | R40: BAY-1 | S40: 1002 | T40: MZK-01
A41: 330000051242 | B41: 11000845 | C41: =VLOOKUP(B41,Equipment!A$1:J$470,9,0) -> E | D41: PUMA V8300-6 | E41: 1002 | F41: Bi Monthly Prev maintenance plan | G41: MSD | H41: MONTH | I41: 03.08.2026 | J41: 03.08.2026 | K41: 03.08.2026 | L41: A302021141 | M41: A | N41: PM03 | P41: 14 | Q41: 1000 | R41: BAY-1 | S41: 1002 | T41: MZK-01
A42: 330000048406 | B42: 11001284 | C42: =VLOOKUP(B42,Equipment!A$1:J$470,9,0) -> E | D42: PAINT BOOTH-3_ROBOTIC_B737 FC | E42: 1001 | F42: AMC FOR ROBO BOOTH | G42: PL1 | H42: MONTH | I42: 03.08.2026 | J42: 03.08.2026 | K42: 03.08.2026 | L42: A101010600 | M42: A | N42: PM03 | P42: 1 | Q42: 1000 | R42: FC-PAINT | S42: 1001 | T42: FC-PAINT
...
